<?xml version="1.0" encoding="UTF-8"?>
<!-- Generated by org.testng.reporters.JUnitReportReporter -->
<testsuite skipped="0" hostname="SK" name="org.test.day1" tests="6" failures="1" timestamp="16 May 2022 09:36:10 GMT" time="0.048" errors="0">
  <testcase name="test1" time="0.004" classname="org.test.day1"/>
  <testcase name="test3" time="0.003" classname="org.test.day1"/>
  <testcase name="test5" time="0.009" classname="org.test.day1"/>
  <testcase name="test" time="0.022" classname="org.test.day1"/>
  <testcase name="test4" time="0.008" classname="org.test.day1">
    <failure type="java.lang.AssertionError" message="The following asserts failed:
	verify test1  expected [true] but found [false],
	verify test3 expected [100] but found [10],
	verify test4 expected [nisha] but found [Nisha]">
      <![CDATA[java.lang.AssertionError: The following asserts failed:
verify test1  expected [true] but found [false],
verify test3 expected [100] but found [10],
verify test4 expected [nisha] but found [Nisha]
at org.testng.asserts.SoftAssert.assertAll(SoftAssert.java:43)
at org.test.day1.test4(day1.java:41)
at sun.reflect.NativeMethodAccessorImpl.invoke0(Native Method)
at sun.reflect.NativeMethodAccessorImpl.invoke(Unknown Source)
at sun.reflect.DelegatingMethodAccessorImpl.invoke(Unknown Source)
at java.lang.reflect.Method.invoke(Unknown Source)
at org.testng.internal.MethodInvocationHelper.invokeMethod(MethodInvocationHelper.java:124)
at org.testng.internal.Invoker.invokeMethod(Invoker.java:583)
at org.testng.internal.Invoker.invokeTestMethod(Invoker.java:719)
at org.testng.internal.Invoker.invokeTestMethods(Invoker.java:989)
at org.testng.internal.TestMethodWorker.invokeTestMethods(TestMethodWorker.java:125)
at org.testng.internal.TestMethodWorker.run(TestMethodWorker.java:109)
at org.testng.TestRunner.privateRun(TestRunner.java:648)
at org.testng.TestRunner.run(TestRunner.java:505)
at org.testng.SuiteRunner.runTest(SuiteRunner.java:455)
at org.testng.SuiteRunner.runSequentially(SuiteRunner.java:450)
at org.testng.SuiteRunner.privateRun(SuiteRunner.java:415)
at org.testng.SuiteRunner.run(SuiteRunner.java:364)
at org.testng.SuiteRunnerWorker.runSuite(SuiteRunnerWorker.java:52)
at org.testng.SuiteRunnerWorker.run(SuiteRunnerWorker.java:84)
at org.testng.TestNG.runSuitesSequentially(TestNG.java:1208)
at org.testng.TestNG.runSuitesLocally(TestNG.java:1137)
at org.testng.TestNG.runSuites(TestNG.java:1049)
at org.testng.TestNG.run(TestNG.java:1017)
at org.testng.remote.AbstractRemoteTestNG.run(AbstractRemoteTestNG.java:132)
at org.testng.remote.RemoteTestNG.initAndRun(RemoteTestNG.java:236)
at org.testng.remote.RemoteTestNG.main(RemoteTestNG.java:81)
]]>
    </failure>
  </testcase> <!-- test4 -->
  <testcase name="test2" time="0.002" classname="org.test.day1"/>
</testsuite> <!-- org.test.day1 -->
